üßæ Fehlerprotokoll mit vollst√§ndigen Tracebacks:


‚ùå Fehler in 'Kategorisierung':
Traceback (most recent call last):
  File "C:\Users\Sascha.Detke\AppData\Local\Programs\Python\Python312\Lib\site-packages\pandas\core\indexes\base.py", line 3812, in get_loc
    return self._engine.get_loc(casted_key)
           ^^^^^^^^^^^^^^^^^^^^^^^^^^^^^^^^
  File "pandas/_libs/index.pyx", line 167, in pandas._libs.index.IndexEngine.get_loc
  File "pandas/_libs/index.pyx", line 196, in pandas._libs.index.IndexEngine.get_loc
  File "pandas/_libs/hashtable_class_helper.pxi", line 7088, in pandas._libs.hashtable.PyObjectHashTable.get_item
  File "pandas/_libs/hashtable_class_helper.pxi", line 7096, in pandas._libs.hashtable.PyObjectHashTable.get_item
KeyError: 'Artikelbezeichnung'

The above exception was the direct cause of the following exception:

Traceback (most recent call last):
  File "C:\Users\Sascha.Detke\OneDrive - Seier Gruppe\Dokumente\RechnungsExtraktionKI\main.py", line 122, in sicher_ausf√ºhren
    return funktion(*args, **kwargs)
           ^^^^^^^^^^^^^^^^^^^^^^^^^
  File "C:\Users\Sascha.Detke\OneDrive - Seier Gruppe\Dokumente\RechnungsExtraktionKI\main.py", line 358, in kategorisiere_artikel_global
    artikel = df["Artikelbezeichnung"].dropna().unique()
              ~~^^^^^^^^^^^^^^^^^^^^^^
  File "C:\Users\Sascha.Detke\AppData\Local\Programs\Python\Python312\Lib\site-packages\pandas\core\frame.py", line 4107, in __getitem__
    indexer = self.columns.get_loc(key)
              ^^^^^^^^^^^^^^^^^^^^^^^^^
  File "C:\Users\Sascha.Detke\AppData\Local\Programs\Python\Python312\Lib\site-packages\pandas\core\indexes\base.py", line 3819, in get_loc
    raise KeyError(key) from err
KeyError: 'Artikelbezeichnung'


‚ùå Kategorisierung schlug fehl. Verarbeitung abgebrochen.

